<?xml version="1.0"?> 
<robot name="arm">
    <link name="big_arm">
        <visual>
            <geometry>
                <cylinder length="0.6" radius="0.05"/>
            </geometry>
        </visual>
        <collision>
            <geometry>
                <cylinder length="0.6" radius="0.05"/>
            </geometry>
        </collision>
    </link>

    <link name="small_arm">
        <visual>
            <geometry>
                <cylinder length="0.4" radius="0.04"/>
            </geometry>
        </visual>
        <collision>
            <geometry>
                <cylinder length="0.4" radius="0.04"/>
            </geometry>
        </collision>
    </link>

    <link name="hand">
        <visual>
            <geometry>
                <box size="0.1 0.1 0.1"/>
            </geometry>
        </visual>
        <collision>
            <geometry>
                <box size="0.1 0.1 0.1"/>
            </geometry>
        </collision>
    </link>

    <joint name="elbow" type="revolute">
        <parent link="big_arm"/>
        <child link="small_arm"/>
        <origin xyz="0.0 0.0 0.30"/>
        <axis xyz="0.0 1.0 0.0"/>
        <limit lower="-1.57" upper="1.57"/>
    </joint>

    <joint name="wrist" type="revolute">
        <parent link="small_arm"/>
        <child link="hand"/>
        <origin xyz="0.0 0.0 0.25"/>
        <axis xyz="0.0 1.0 0.0"/>
        <limit lower="-1.57" upper="1.57"/>
    </joint>
</robot>